Workbook

Sheet Summary
A1: QA Test Case Summary — All Modules
A2: Counts update automatically from each module's Status column. Test every module in both English and Arabic UI language.
A3: Module | B3: Total Test Cases | C3: Pass | D3: Fail | E3: Blocked | F3: Not Executed | G3: % Complete
A4: Departments | B4: =COUNTA(Departments!A4:A10000) | C4: =COUNTIF(Departments!F4:F10000,"Pass") | D4: =COUNTIF(Departments!F4:F10000,"Fail") | E4: =COUNTIF(Departments!F4:F10000,"Blocked") | F4: =COUNTIF(Departments!F4:F10000,"Not Executed") | G4: =IFERROR(C4/B4,0)
A5: SMS Broadcast | B5: =COUNTA('SMS Broadcast'!A4:A10000) | C5: =COUNTIF('SMS Broadcast'!F4:F10000,"Pass") | D5: =COUNTIF('SMS Broadcast'!F4:F10000,"Fail") | E5: =COUNTIF('SMS Broadcast'!F4:F10000,"Blocked") | F5: =COUNTIF('SMS Broadcast'!F4:F10000,"Not Executed") | G5: =IFERROR(C5/B5,0)
A6: Push Broadcast | B6: =COUNTA('Push Broadcast'!A4:A10000) | C6: =COUNTIF('Push Broadcast'!G4:G10000,"Pass") | D6: =COUNTIF('Push Broadcast'!G4:G10000,"Fail") | E6: =COUNTIF('Push Broadcast'!G4:G10000,"Blocked") | F6: =COUNTIF('Push Broadcast'!G4:G10000,"Not Executed") | G6: =IFERROR(C6/B6,0)
A7: Inbox Broadcast | B7: =COUNTA('Inbox Broadcast'!A4:A10000) | C7: =COUNTIF('Inbox Broadcast'!G4:G10000,"Pass") | D7: =COUNTIF('Inbox Broadcast'!G4:G10000,"Fail") | E7: =COUNTIF('Inbox Broadcast'!G4:G10000,"Blocked") | F7: =COUNTIF('Inbox Broadcast'!G4:G10000,"Not Executed") | G7: =IFERROR(C7/B7,0)
A8: MessageTemplate | B8: =COUNTA(MessageTemplate!A4:A10000) | C8: =COUNTIF(MessageTemplate!G4:G10000,"Pass") | D8: =COUNTIF(MessageTemplate!G4:G10000,"Fail") | E8: =COUNTIF(MessageTemplate!G4:G10000,"Blocked") | F8: =COUNTIF(MessageTemplate!G4:G10000,"Not Executed") | G8: =IFERROR(C8/B8,0)
A9: User Management | B9: =COUNTA('User Management'!A4:A10000) | C9: =COUNTIF('User Management'!F4:F10000,"Pass") | D9: =COUNTIF('User Management'!F4:F10000,"Fail") | E9: =COUNTIF('User Management'!F4:F10000,"Blocked") | F9: =COUNTIF('User Management'!F4:F10000,"Not Executed") | G9: =IFERROR(C9/B9,0)
A10: CreditReports | B10: =COUNTA(CreditReports!A4:A10000) | C10: =COUNTIF(CreditReports!G4:G10000,"Pass") | D10: =COUNTIF(CreditReports!G4:G10000,"Fail") | E10: =COUNTIF(CreditReports!G4:G10000,"Blocked") | F10: =COUNTIF(CreditReports!G4:G10000,"Not Executed") | G10: =IFERROR(C10/B10,0)
A11: Reports | B11: =COUNTA(Reports!A4:A10000) | C11: =COUNTIF(Reports!F4:F10000,"Pass") | D11: =COUNTIF(Reports!F4:F10000,"Fail") | E11: =COUNTIF(Reports!F4:F10000,"Blocked") | F11: =COUNTIF(Reports!F4:F10000,"Not Executed") | G11: =IFERROR(C11/B11,0)
A12: Credit Management | B12: =COUNTA('Credit Management'!A4:A10000) | C12: =COUNTIF('Credit Management'!F4:F10000,"Pass") | D12: =COUNTIF('Credit Management'!F4:F10000,"Fail") | E12: =COUNTIF('Credit Management'!F4:F10000,"Blocked") | F12: =COUNTIF('Credit Management'!F4:F10000,"Not Executed") | G12: =IFERROR(C12/B12,0)
A13: Home-Header | B13: =COUNTA('Home-Header'!A4:A10000) | C13: =COUNTIF('Home-Header'!F4:F10000,"Pass") | D13: =COUNTIF('Home-Header'!F4:F10000,"Fail") | E13: =COUNTIF('Home-Header'!F4:F10000,"Blocked") | F13: =COUNTIF('Home-Header'!F4:F10000,"Not Executed") | G13: =IFERROR(C13/B13,0)
A14: Login | B14: =COUNTA(Login!A4:A10000) | C14: =COUNTIF(Login!F4:F10000,"Pass") | D14: =COUNTIF(Login!F4:F10000,"Fail") | E14: =COUNTIF(Login!F4:F10000,"Blocked") | F14: =COUNTIF(Login!F4:F10000,"Not Executed") | G14: =IFERROR(C14/B14,0)
A15: General-CrossCutting | B15: =COUNTA('General-CrossCutting'!A4:A10000) | C15: =COUNTIF('General-CrossCutting'!F4:F10000,"Pass") | D15: =COUNTIF('General-CrossCutting'!F4:F10000,"Fail") | E15: =COUNTIF('General-CrossCutting'!F4:F10000,"Blocked") | F15: =COUNTIF('General-CrossCutting'!F4:F10000,"Not Executed") | G15: =IFERROR(C15/B15,0)
A16: TOTAL | B16: =SUM(B4:B15) | C16: =SUM(C4:C15) | D16: =SUM(D4:D15) | E16: =SUM(E4:E15) | F16: =SUM(F4:F15) | G16: =SUM(G4:G15)

Sheet Departments
A1: Dictionaries — Test Cases
A2: Execute each test case in both English and Arabic UI language. Select Status from the dropdown: Pass / Fail / Blocked / Not Executed.
A3: Test Case ID | B3: Test Scenario | C3: Precondition | D3: Test Steps | E3: Expected Result | F3: Status | G3: Actual Result | H3: Tested By | I3: Date Tested | J3: Remarks
A4: TC-DIC-001 | B4: Verify that the correct fields and controls are displayed on the Add Department form | C4: 1. The user must be logged in to the PuffinMT UI._x000D_ 2. The user must have access to the Departments tab. | D4: 1. Open the Departments page._x000D_ 2. Review the input fields on the Add Department form. | E4: The following fields and controls should be displayed on the Add Department form:_x000D_ 1. English Name_x000D_ 2. Arabic Name_x000D_ 3. Value_x000D_ 4. Active_x000D_ 5. Inactive_x000D_ 6. Reset button_x000D_ 7. Submit button | F4: Pass | H4: Automation Bot | I4: 2026-10-08 13:34
A5: TC-DIC-002 | B5: Verify the validation messages when all fields are empty | C5: 1. The user must be logged in to the PuffinMT UI._x000D_ 2. The user must have access to the Departments tab. | D5: 1. Open the Departments page._x000D_ 2. Click Add Department._x000D_ 3. Leave all fields empty and click Submit. | E5: When all fields are empty and the user clicks the Submit button, appropriate validation messages should be displayed. | F5: Pass | H5: Automation Bot | I5: 2026-10-08 13:34
A6: TC-DIC-003 | B6: Verify the mandatory fields on the Add Department form | C6: 1. The user must be logged in to the PuffinMT UI._x000D_ 2. The user must have access to the Departments tab. | D6: 1. Open the Departments page._x000D_ 2. Click Add Department._x000D_ 3. Identify the fields marked as mandatory. | E6: An asterisk should be displayed beside each mandatory field. | F6: Pass | H6: Automation Bot | I6: 2026-10-08 13:35
A7: TC-DIC-004 | B7: Verify alphanumeric input in the 'English Name' field | C7: 1. The user must be logged in to the PuffinMT UI._x000D_ 2. The user must have access to the Departments tab. | D7: 1. Open the Departments page._x000D_ 2. Click Add Department._x000D_ 3. Enter alphanumeric characters in the 'English Name' field. | E7: The 'English Name' field should accept alphanumeric characters. | F7: Pass | H7: Automation Bot | I7: 2026-10-08 13:35
A8: TC-DIC-005 | B8: Verify alphanumeric and Arabic input in the 'Arabic Name' field | C8: 1. The user must be logged in to the PuffinMT UI._x000D_ 2. The user must have access to the Departments tab. | D8: 1. Open the Departments page._x000D_ 2. Click Add Department._x000D_ 3. Enter alphanumeric and Arabic characters in the 'Arabic Name' field. | E8: The 'Arabic Name' field should accept alphanumeric and Arabic characters. | F8: Pass | H8: Automation Bot | I8: 2026-10-08 13:36
A9: TC-DIC-006 | B9: Verify alphanumeric input in the 'Value' field | C9: 1. The user must be logged in to the PuffinMT UI._x000D_ 2. The user must have access to the Departments tab. | D9: 1. Open the Departments page._x000D_ 2. Click Add Department._x000D_ 3. Enter alphanumeric characters in the 'Value' field. | E9: The 'Value' field should accept alphanumeric input. | F9: Pass | H9: Automation Bot | I9: 2026-10-08 13:37
A10: TC-DIC-007 | B10: Verify the minimum and maximum character limits for the 'Value' field | C10: 1. The user must be logged in to the PuffinMT UI._x000D_ 2. The user must have access to the Departments tab. | D10: 1. Open the Departments page._x000D_ 2. Click Add Department._x000D_ 3. Test the minimum and maximum character limits of the 'Value' field. | E10: The 'Value' field should accept a minimum of 3 characters and a maximum of 50 characters. | F10: Pass | H10: Automation Bot | I10: 2026-10-08 13:37
A11: TC-DIC-008 | B11: Verify the 'Active' and 'Inactive' radio buttons | C11: 1. The user must be logged in to the PuffinMT UI._x000D_ 2. The user must have access to the Departments tab. | D11: 1. Open the Departments page._x000D_ 2. Click Add Department._x000D_ 3. Review the 'Active' and 'Inactive' radio buttons. | E11: The 'Active' radio button should be selected by default, and the user should also be able to select the 'Inactive' radio button. | F11: Pass | H11: Automation Bot | I11: 2026-10-08 13:38
A12: TC-DIC-009 | B12: Verify that a department can be added with valid details | C12: 1. The user must be logged in to the PuffinMT UI._x000D_ 2. The user must have access to the Departments tab. | D12: 1. Open the Departments page._x000D_ 2. Click Add Department._x000D_ 3. Enter valid details in all required fields._x000D_ 4. Click Submit. | E12: When all details are valid and the user clicks the Submit button, the department should be added and displayed at the top of the list. | F12: Pass | H12: Automation Bot | I12: 2026-10-08 13:39
A13: TC-DIC-010 | B13: Verify filtering by 'English Name' using the 'Contains' condition | C13: 1. The user must be logged in to the PuffinMT UI._x000D_ 2. The user must have access to the Departments tab. | D13: 1. Select 'English Name' from the filter dropdown._x000D_ 2. Choose the 'Contains' condition._x000D_ 3. Verify that the search field appears._x000D_ 4. Enter 'John' in the search field._x000D_ 5. Click Apply/Search. | E13: Only records where the 'English Name' field contains the entered value should be displayed. | F13: Pass | H13: Automation Bot | I13: 2026-10-08 13:39
A14: TC-DIC-011 | B14: Verify filtering by 'English Name' using the 'Starts With' condition | C14: 1. The user must be logged in to the PuffinMT UI._x000D_ 2. The user must have access to the Departments tab. | D14: 1. Select 'English Name' from the filter dropdown._x000D_ 2. Choose the 'Starts With' condition._x000D_ 3. Enter the prefix 'Jo' in the search field._x000D_ 4. Click Apply/Search. | E14: Only records where the 'English Name' field starts with the entered value should be displayed. | F14: Pass | H14: Automation Bot | I14: 2026-10-08 13:39
A15: TC-DIC-012 | B15: Verify filtering by 'English Name' using the 'Ends With' condition | C15: 1. The user must be logged in to the PuffinMT UI._x000D_ 2. The user must have access to the Departments tab. | D15: 1. Select 'English Name' from the filter dropdown._x000D_ 2. Choose the 'Ends With' condition._x000D_ 3. Enter the suffix 'son' in the search field._x000D_ 4. Click Apply/Search. | E15: Only records where the 'English Name' field ends with the entered value should be displayed. | F15: Pass | H15: Automation Bot | I15: 2026-10-08 13:40
... A72: TC-DIC-069 | B72: Verify that the Last Login date and time are displayed | C72: 1. The user must be logged in._x000D_ 2. The user must have access to the Dictionary > Department tab. | D72: 1. Navigate to Dictionary > Department._x000D_ 2. Review the header or navigation bar._x000D_ 3. Locate the Last Login information. | E72: The Last Login field should display the date and time of the user's previous login. | F72: Pass | H72: Automation Bot | I72: 2026-10-08 14:00

Sheet SMS Broadcast
A1: SMS Broadcast — Test Cases
A2: Execute each test case in both English and Arabic UI language. Select Status from the dropdown: Pass / Fail / Blocked / Not Executed.
A3: Test Case ID | B3: Test Scenario | C3: Precondition | D3: Test Steps | E3: Expected Result | F3: Status | G3: Actual Result | H3: Tested By | I3: Date Tested | J3: Remarks
A4: TC-BC-01 | B4: Verify Add Broadcast opens a clean SMS broadcast creation form. | C4: The user has permission to create SMS broadcasts. | D4: 1. Log in and open Broadcast > SMS. 2. Select Add Broadcast. 3. Verify the create page title and that all SMS-specific fields are displayed. 4. Confirm that no values from a previously viewed broadcast remain populated. 5. Use Back or Cancel and verify the listing reopens without creating a record. 6. Repeat in the Arabic UI. | E4: Add Broadcast opens the correct SMS creation form without error or stale data; all labels and controls are visible, and leaving without submission creates no broadcast in either language. | F4: Not Executed | G4: Automated check passed. | H4: Automation Bot | I4: 2026-08-11 12:25
A5: TC-BC-02 | B5: Verify that From and To date filters return only SMS broadcasts within inclusive boundaries. | C5: SMS broadcasts exist before, on, and after known boundary dates. | D5: 1. open Broadcast > SMS. 2. Apply a valid From and To range containing known records. 3. Compare each displayed Scheduled Date Time or Created On value with the selected boundaries. 4. Confirm records on both boundary dates are included and out-of-range records are excluded. 5. Test a single-day range and then an invalid range where From is later than To. 6. Clear the filters and repeat in Arabic. | E5: Only records within the inclusive valid range are shown, a single-day range works, clearing restores the full authorized list, and an invalid range is blocked with a clear localized message. | F5: Not Executed | G5: Automated check passed. | H5: Automation Bot | I5: 2026-08-11 12:25
A6: TC-BC-03 | B6: Verify Broadcast Name search returns accurate SMS matches and handles no-result input. | C6: At least two SMS broadcasts have distinct known names. | D6: 1. open Broadcast > SMS. 2. Enter a complete existing Broadcast Name and submit the search. 3. Search using a unique partial value and different letter casing. 4. Verify every returned row matches the entered value according to the defined search behavior. 5. Search for a nonexistent name, then clear the search. 6. Repeat in Arabic. | E6: Exact and supported partial/case searches return only matching SMS broadcasts, nonexistent input shows a localized no-data state, and clearing the search restores the authorized list. | F6: Not Executed | G6: Automated check passed. | H6: Automation Bot | I6: 2026-08-11 12:25
A7: TC-BC-04 | B7: Verify SMS listing columns sort correctly in ascending and descending order. | C7: The SMS list contains varied names, dates, and creators. | D7: 1. open Broadcast > SMS. 2. Select the Broadcast Name header and record the ascending order; select it again for descending order. 3. Repeat for Scheduled Date Time, Created By, and Created On. 4. Verify first, middle, and last rows after each sort. 5. Confirm blank values, if present, are positioned consistently. 6. Repeat in Arabic. | E7: Each supported header toggles between correct ascending and descending order using the appropriate text or date-time comparison, with no missing or duplicated rows in either language. | F7: Not Executed | G7: Automated check passed. | H7: Automation Bot | I7: 2026-08-11 12:25
A8: TC-BC-05 | B8: Verify each SMS row displays the correct channel tag and recipient-count badge. | C8: Use SMS broadcasts with known recipient counts, including one and multiple recipients. | D8: 1. open Broadcast > SMS. 2. Locate the selected broadcasts by name. 3. Confirm each row displays the SMS tag. 4. Compare the recipient badge with the recipients accepted when the broadcast was created or with the approved source record. 5. Verify singular, multiple-recipient, and zero-recipient handling where supported. 6. Repeat in Arabic. | E8: Every selected row shows the correct SMS tag and an accurate recipient count; labels and numerals are consistent in both languages. | F8: Not Executed | G8: Automated check passed. | H8: Automation Bot | I8: 2026-08-11 12:25
A9: TC-BC-06 | B9: Verify the SMS row action menu and advanced filters show authorized options and apply correctly. | C9: The list contains SMS broadcasts in different statuses and the test role's permissions are known. | D9: 1. open Broadcast > SMS and open the three-dot menu for a known row. 2. Verify only actions permitted for its status and the logged-in role are shown. 3. Execute each non-destructive option and verify it targets the selected broadcast. 4. Open advanced filters, apply each available criterion individually and in combination. 5. Clear all criteria and confirm the original list returns. 6. Repeat in Arabic. | E9: Menus open for the correct row, unauthorized actions are hidden or disabled, permitted actions work as designed, and advanced filters return only matching records and can be cleared in both languages. | F9: Not Executed | G9: Automated check passed. | H9: Automation Bot | I9: 2026-08-11 12:25
A10: TC-BC-07 | B10: Verify Regular and Custom modes display the correct SMS form fields without retaining incompatible values. | C10: The user can create SMS broadcasts. | D10: 1. Open the SMS creation form. 2. Note the default mode and its visible required fields. 3. Enter distinguishable test values, then switch to the other mode. 4. Verify that the field set and required indicators change according to the selected mode. 5. Switch back and verify whether values are retained or cleared according to the approved design. 6. Repeat in Arabic. | E10: The selected mode is visually clear, only its applicable fields and validations are active, incompatible values are not submitted, and mode switching behaves consistently in both languages. | F10: Not Executed | G10: Automated check passed. | H10: Automation Bot | I10: 2026-08-11 12:25
A11: TC-BC-08 | B11: Verify Broadcast Name is mandatory and accepts only valid SMS name input. | C11: The user can create SMS broadcasts, and a unique valid name plus values for all other mandatory fields are available. | D11: 1. Open the SMS create form. 2. Leave Broadcast Name blank, complete other mandatory fields with valid data, and submit. 3. Repeat using spaces only. 4. Enter a valid unique name containing allowed characters and submit again. 5. If a documented maximum length exists, test values at and above the limit. 6. Repeat in Arabic. | E11: Blank or whitespace-only names are rejected with a clear message beside the field; valid input is accepted, documented length rules are enforced, and the entered name displays correctly in both languages. | F11: Not Executed | G11: Automated check passed. | H11: Automation Bot | I11: 2026-08-11 12:25
A12: TC-BC-09 | B12: Verify Department is required and lists only departments available to the logged-in user for SMS broadcasts. | C12: The test user has access to known departments and is restricted from at least one department if role rules support it. | D12: 1. Open the SMS create form and expand Department. 2. Compare available values with the user's authorized department list. 3. Leave Department unselected and attempt submission with all other mandatory fields valid. 4. Select an authorized department and continue. 5. Search or scroll for duplicate, inactive, or unauthorized entries. 6. Repeat in Arabic. | E12: The dropdown loads without duplicates, contains only authorized active departments, blocks submission when blank, and accepts a valid selection with correct localized text. | F12: Not Executed | G12: Automated check passed. | H12: Automation Bot | I12: 2026-08-11 12:25
A13: TC-BC-10 | B13: Verify SMS Sender ID is mandatory and lists only authorized active sender IDs for the selected department. | C13: The selected department has known active, inactive, and unauthorized sender IDs. | D13: 1. Open the SMS create form, select the department, and expand Sender ID. 2. Compare the list with the authorized active sender IDs. 3. Leave Sender ID blank and attempt submission with other mandatory fields valid. 4. Select a valid sender ID, change the department, and verify the list refreshes. 5. Confirm inactive, duplicate, or unauthorized IDs are absent. 6. Repeat in Arabic. | E13: Sender ID is required, the list contains each authorized active ID once for the selected department. Department changes refresh it correctly, and invalid IDs cannot be submitted. | F13: Not Executed | G13: Automated check passed. | H13: Automation Bot | I13: 2026-08-11 12:25
A14: TC-BC-11 | B14: Verify Send Now and Schedule Later modes control SMS scheduling and date-time validation correctly. | C14: The user can create SMS broadcasts, and valid future date-time values are available. | D14: 1. Open the SMS create form and note the default scheduling mode. 2. Select Send Now and verify no future date-time is required. 3. Select Schedule Later and confirm a date-time picker appears and becomes mandatory. 4. Attempt to select a past time, then select a valid future time in the application's configured time zone. 5. Switch modes and verify hidden schedule values are not submitted unexpectedly. 6. Repeat in Arabic. | E14: Send Now requires no future date, Schedule Later requires and accepts only a valid future date-time, past values are rejected, and the selected time is retained and displayed in the correct time zone in both languages. | F14: Not Executed | G14: Automated check passed. | H14: Automation Bot | I14: 2026-08-11 12:26
A15: TC-BC-12 | B15: Verify SMS recipient sample files download in Excel and CSV formats with the required template structure. | C15: The user can create SMS broadcasts and has permission to download files from the creation form. | D15: 1. Open the SMS create form. 2. Select the Excel sample-file icon and open the downloaded file. 3. Select the CSV icon and open that file. 4. Compare file names, headers, column order, example values, encoding, and mandatory-field guidance with the upload specification. 5. Confirm the templates can be populated and saved without corruption. 6. Repeat from the Arabic UI. | E15: Both sample files download and open successfully, use meaningful file names and the documented SMS recipient schema, preserve readable English/Arabic text, and are accepted as upload templates after valid data is added. | F15: Not Executed | G15: Automated check passed. | H15: Automation Bot | I15: 2026-08-11 12:26
... A151: TC-BC-148 | B151: Verify Edit and Cancel actions are removed after a broadcast crosses the buffer threshold. | C151: The user has edit and cancel permissions; both buffers are 6 minutes; a broadcast is approaching the threshold. | D151: 1. Confirm Edit and Cancel actions are available while remaining time is greater than 6 minutes. 2. Wait until remaining time is 6 minutes or less. 3. Refresh the broadcast list. 4. Observe the Actions column. | E151: After refresh, Edit and Cancel actions should no longer be available once the remaining schedule time reaches or falls below the configured buffer. | F151: Not Executed | G151: Automated check passed. | H151: Automation Bot | I151: 2026-08-11 12:26

Sheet Push Broadcast
A1: Push Broadcast — Test Cases
A2: Execute each test case in both English and Arabic UI language. Select Status from the dropdown: Pass / Fail / Blocked / Not Executed.
A3: Test Case ID | B3: Test Scenario | C3: Precondition | D3: Test Steps | E3: Expected Result | F3: Priority | G3: Status | H3: Actual Result | I3: Tested By | J3: Date Tested | K3: Remarks
A4: TC-BC-01 | B4: Verify Add Broadcast opens a clean Push broadcast creation form. | C4: The user has permission to create Push broadcasts. | D4: 1. Log in and open Broadcast > Push. 2. Select Add Broadcast. 3. Verify the create page title and all Push-specific fields are displayed. 4. Confirm no values from a previously viewed broadcast remain populated. 5. Use Back or Cancel and verify the listing reopens without creating a record. 6. Repeat in the Arabic UI. | E4: Add Broadcast opens the correct Push creation form without error or stale data; all labels and controls are visible, and leaving without submission creates no broadcast in either language. | F4: Medium | G4: Pass | H4: Automated check passed. | I4: Automation Bot | J4: 2026-08-11 12:23
A5: TC-BC-02 | B5: Verify From and To date filters return only Push broadcasts within inclusive boundaries. | C5: Push broadcasts exist before, on, and after known boundary dates. | D5: 1. Open Broadcast > Push. 2. Apply a valid From and To range containing known records. 3. Compare each displayed Scheduled Date Time or Created On value with the selected boundaries. 4. Confirm records on both boundary dates are included, and out-of-range records are excluded. 5. Test a single-day range and then an invalid range where From is later than To. 6. Clear the filters and repeat in Arabic. | E5: Only records within the inclusive valid range are shown, a single-day range works, clearing restores the full authorized list, and an invalid range is blocked with a clear localized message. | F5: Medium | G5: Pass | H5: Automated check passed. | I5: Automation Bot | J5: 2026-08-11 12:24
A6: TC-BC-03 | B6: Verify Broadcast Name search returns accurate Push matches and handles no-result input. | C6: At least two Push broadcasts have dis,tinct known names. | D6: 1. Open Broadcast > Push. 2. Enter a complete existing Broadcast Name and submit the search. 3. Search using a unique partial value and different letter casing. 4. Verify that every returned row matches the entered value according to the defined search behavior. 5. Search for a nonexistent name, then clear the search. 6. Repeat in Arabic. | E6: Exact and supported partial/case searches return only matching Push broadcasts, nonexistent input shows a localized no-data state, and clearing the search restores the authorized list. | F6: Medium | G6: Pass | H6: Automated check passed. | I6: Automation Bot | J6: 2026-08-11 12:24
A7: TC-BC-04 | B7: Verify Push listing columns sort correctly in ascending and descending order. | C7: aThe Push list contains variety ofvaried names, dates, and cre | D7: 1. Open Broadcast > Push. 2. Select the Broadcast Name header and record the ascending order; select it again for descending order. 3. Repeat for Scheduled Date Time, Created By, and Created On. 4. Check first, middle, and last rows after each sort. 5. Confirm blank values, if present, are positioned consistently. 6. Repeat in Arabic. | E7: Each supported header toggles between correct ascending and descending order using the appropriate text or date-time comparison, with no missing or duplicated rows in either language. | F7: Low | G7: Pass | H7: Automated check passed. | I7: Automation Bot | J7: 2026-08-11 12:24
A8: TC-BC-05 | B8: Verify each Push row displays the correct channel tag and recipient-count badge. | C8: Use Push broadcasts with known recipient counts, including one and multiple recipients. | D8: 1. Open Broadcast > Push. 2. Locate the selected broadcasts by name. 3. Confirm each row displays the Push tag. 4. Compare the recipient badge with the recipients accepted when the broadcast was created or with the approved source record. 5. Check singular, multiple-recipient, and zero-recipient handling where supported. 6. Repeat in Arabic. | E8: Every selected row shows the correct Push tag and an accurate recipient count; labels, numerals, and singular/plural presentation are readable and consistent in both languages. | F8: Medium | G8: Pass | H8: Automated check passed. | I8: Automation Bot | J8: 2026-08-11 12:24
A9: TC-BC-06 | B9: Verify the Push row action menu and advanced filters show authorized options and apply correctly. | C9: The list contains Push broadcasts in different statuses and the test role's permissions are known. | D9: 1. Open Broadcast > Push and open the three-dot menu for a known row. 2. Verify only actions permitted for its status and the logged-in role are shown. 3. Execute each non-destructive option and verify it targets the selected broadcast. 4. Open advanced filters, apply each available criterion individually and in combination. 5. Clear all criteria and confirm the original list returns. 6. Repeat in Arabic. | E9: Menus open for the correct row, unauthorized actions are hidden or disabled, permitted actions work as designed, and advanced filters return only matching records and can be cleared in both languages. | F9: Medium | G9: Pass | H9: Automated check passed. | I9: Automation Bot | J9: 2026-08-11 12:24
A10: TC-BC-07 | B10: Verify that Regular and Custom modes display the correct Push form fields without retaining incompatible values. | C10: The user can create Push broadcasts. | D10: 1. Open the Push create form. 2. Note the default mode and its visible required fields. 3. Enter distinguishable test values, then switch to the other mode. 4. Verify the field set and required indicators change according to the selected mode. 5. Switch back and check whether values are retained or cleared according to the approved design. 6. Repeat in Arabic. | E10: The selected mode is visually clear, only its applicable fields and validations are active, incompatible values are not submitted, and mode switching behaves consistently in both languages. | F10: Medium | G10: Pass | H10: Automated check passed. | I10: Automation Bot | J10: 2026-08-11 12:24
A11: TC-BC-08 | B11: Verify Broadcast Name is mandatory and accepts only valid Push name input. | D11: 1. Open the Push create form. 2. Leave Broadcast Name blank, complete other mandatory fields with valid data, and submit. 3. Repeat using spaces only. 4. Enter a valid, unique name containing allowed characters and submit again. 5. If a documented maximum length exists, test values at and above the limit. 6. Repeat in Arabic. | E11: Blank or whitespace-only names are rejected with a clear message beside the field; valid input is accepted, documented length rules are enforced, and the entered name displays correctly in both languages. | F11: High | G11: Pass | H11: Automated check passed. | I11: Automation Bot | J11: 2026-08-11 12:24
A12: TC-BC-09 | B12: Verify Department is required and lists only departments available to the logged-in user for Push broadcasts. | C12: The test user has access to known departments and is restricted from at least one department if role rules support it. | D12: 1. Open the Push create form and expand Department. 2. Compare available values with the user's authorized department list. 3. Leave Department unselected and attempt submission with all other mandatory fields valid. 4. Select an authorized department and continue. 5. Search or scroll for duplicate, inactive, or unauthorized entries. 6. Repeat in Arabic. | E12: The dropdown loads without duplicates, contains only authorized active departments, blocks submission when blank, and accepts a valid selection with correct localized text. | F12: High | G12: Pass | H12: Automated check passed. | I12: Automation Bot | J12: 2026-08-11 12:24
A13: TC-BC-10 | B13: Verify Send Now and Schedule Later modes control Push scheduling and date-time validation correctly. | D13: 1. Open the Push create form and note the default scheduling mode. 2. Select Send Now and verify no future date-time is required. 3. Select Schedule Later and confirm a date-time picker appears and becomes mandatory. 4. Attempt to select a past time, then select a valid future time in the application's configured time zone. 5. Switch modes and verify hidden schedule values are not submitted unexpectedly. 6. Repeat in Arabic. | E13: Send Now requires no future date, Schedule Later requires and accepts only a valid future date-time, past values are rejected, and the selected time is retained and displayed in the correct time zone in both languages. | F13: Medium | G13: Pass | H13: Automated check passed. | I13: Automation Bot | J13: 2026-08-11 12:24
A14: TC-BC-11 | B14: Verify Push recipient sample files download in Excel and CSV formats with the required template structure. | D14: 1. Open the Push create form. 2. Select the Excel sample-file icon and open the downloaded file. 3. Select the CSV icon and open that file. 4. Compare file names, headers, column order, example values, encoding, and mandatory-field guidance with the upload specification. 5. Confirm the templates can be populated and saved without corruption. 6. Repeat from the Arabic UI. | E14: Both sample files download and open successfully, use meaningful file names and the documented Push recipient schema, preserve readable English/Arabic text, and are accepted as upload templates after valid data is added. | F14: Medium | G14: Pass | H14: Automated check passed. | I14: Automation Bot | J14: 2026-08-11 12:24
A15: TC-BC-12 | B15: Verify Push recipient upload accepts valid Excel/CSV files and rejects unsupported or malformed files. | C15: Prepare valid Excel and CSV files, as well as files with unsupported extensions, missing headers, invalid rows, and excessive size if a limit is documented. | D15: 1. Open the Push create form and upload each valid file. 2. Verify the selected file name and accepted recipient count. 3. Replace it with each invalid file and observe validation. 4. Confirm invalid files cannot be submitted and errors identify the reason or row where applicable. 5. Remove the file and verify the control resets. 6. Repeat in Arabic. | E15: Valid Excel/CSV files upload with the correct name and recipient count; unsupported, malformed, or oversized files are rejected without partial submission and show clear localized validation. | F15: High | G15: Pass | H15: Automated check passed. | I15: Automation Bot | J15: 2026-08-11 12:24
A16: TC-BC-13 | B16: Verify the Push recipient Group dropdown loads authorized groups and applies the selected membership accurately. | C16: Known active, inactive, empty, and unauthorized recipient groups exist where supported. | D16: 1. Open the Push create form and expand Group. 2. Compare displayed groups with the test user's authorized active groups. 3. Select a known group and compare the shown recipient count with its current valid membership. 4. Change to another group and confirm the count refreshes. 5. Check that inactive, unauthorized, or duplicate groups are absent. 6. Repeat in Arabic. | E16: The dropdown lists each authorized active group once, selection updates the recipient set/count accurately, and unauthorized or inactive groups are not exposed in either language. | F16: Medium | G16: Pass | H16: Automated check passed. | I16: Automation Bot | J16: 2026-08-11 12:24
A17: TC-BC-14 | B17: Verify Manual Entry accepts semicolon-separated valid push tokens and calculates recipients correctly. | C17: Prepare at least three known-valid push tokens, including the exact supported delimiter format. | D17: 1. Open the Push create form and choose Manual Entry. 2. Enter one valid value and verify it is recognized. 3. Enter multiple valid values separated by semicolons, with and without a trailing semicolon. 4. Add leading/trailing spaces and a duplicate value to check normalization and duplicate handling. 5. Compare the accepted recipient count with the unique valid entries. 6. Repeat in Arabic. | E17: All correctly formatted values are accepted, delimiters and surrounding spaces are handled according to specification, duplicates are not unintentionally counted twice, and the displayed recipient count is accurate. | F17: High | G17: Pass | H17: Automated check passed. | I17: Automation Bot | J17: 2026-08-11 12:24
A18: TC-BC-15 | B18: Verify that exactly one Push recipient method is required and that conflicting methods cannot be submitted together. | D18: 1. Open the Push create form and complete all non-recipient mandatory fields. 2. Submit without File, Group, or Manual Entry. 3. Select File and confirm the other methods are cleared or disabled as designed. 4. Repeat separately with Group and Manual Entry. 5. Attempt to populate two methods by switching controls or using the approved UI test method. 6. Repeat in Arabic. | E18: Submission is blocked when no recipient method is supplied; each valid method works independently, and the system prevents or resolves multiple active methods so recipients cannot be duplicated or ambiguously sourced. | F18: High | G18: Pass | H18: Automated check passed. | I18: Automation Bot | J18: 2026-08-11 12:24
A19: TC-BC-16 | B19: Verify Push Application lists only authorized active applications and retains the selected application. | C19: Active, inactive, and unauthorized push applications exist, including Mobile_Application if configured. | D19: 1. Open the Push create form and expand Push Application. 2. Compare displayed values with the user's authorized active applications. 3. Select a known application and verify dependent templates or fields refresh correctly. 4. Change the selection and confirm the new value is retained. 5. Check that inactive, unauthorized, and duplicate entries are absent. 6. Repeat in Arabic. | E19: Each authorized active push application appears once, selection is retained and drives the correct dependent options, and unauthorized or inactive applications are not exposed. | F19: Medium | G19: Pass | H19: Automated check passed. | I19: Automation Bot | J19: 2026-08-11 12:24
A20: TC-BC-17 | B20: Verify User Field lists valid USERFIELDPUSH mappings and applies the selected mapping to Push recipients. | C20: At least two active USERFIELDPUSH mappings with known recipient data exist. | D20: 1. Open the Push create form and expand User Field. 2. Compare displayed entries with the configured active USERFIELDPUSH mappings. 3. Select each known mapping and verify its label/value is retained. 4. Complete the form with compatible recipient data and submit a test broadcast. 5. Confirm recipient resolution uses the selected field and inactive/duplicate mappings are absent. 6. Repeat in Arabic. | E20: The dropdown loads each active USERFIELDPUSH mapping once, retains the selection, resolves recipients using that field, and does not expose invalid or inactive mappings in either language. | F20: Medium | G20: Pass | H20: Automated check passed. | I20: Automation Bot | J20: 2026-08-11 12:25
A21: TC-BC-18 | B21: Verify Template Name is mandatory and lists only active templates compatible with Push and the selected context. | C21: Active, inactive, and channel-incompatible templates exist. | D21: 1. Open the Push create form and expand Template Name after selecting the required context fields. 2. Compare the list with approved active Push templates. 3. Leave it blank and attempt submission. 4. Select a valid template and verify that any preview or mapped fields use the correct content. 5. Confirm inactive, unauthorized, or incompatible templates are absent. 6. Repeat in Arabic. | E21: Only authorized active Push templates are listed, blank selection blocks submission, the selected template is retained and renders the correct content, and incompatible templates are not exposed. | F21: High | G21: Pass | H21: Automated check passed. | I21: Automation Bot | J21: 2026-08-11 12:25
A22: TC-BC-19 | B22: Verify Schedule creates one valid Push broadcast and provides an unambiguous confirmation. | C22: Prepare valid, unique broadcast data and a known recipient set. | D22: 1. Open the Push create form and complete every mandatory field with valid data. 2. Review name, department, schedule, recipient source, and template. 3. Select Schedule once and observe button state while processing. 4. Record the success message and any generated reference. 5. Refresh the listing and search for the unique name. 6. Repeat with a second unique case in Arabic. | E22: One broadcast is created per submission, duplicate clicks are prevented, a clear localized success message appears, and the saved record retains the submitted values with no duplicate entry. | F22: Medium | G22: Blocked | H22: Test skipped/blocked. | I22: Automation Bot | J22: 2026-08-11 12:25
A23: TC-BC-20 | B23: Verify a newly created Push broadcast appears in the listing with accurate schedule, creator, recipients, and channel tag. | C23: Create a uniquely named Push broadcast with a known future schedule and recipient count. | D23: 1. Return to Broadcast > Push after successful creation. 2. Search for the unique Broadcast Name. 3. Compare Scheduled Date Time, Created By, Created On, recipient count, and Push tag with the submitted values and the logged-in user. 4. Refresh the page and repeat the comparison. 5. Confirm that no duplicate row exists. 6. Repeat in Arabic. | E23: Exactly one matching row appears and persists after refresh; its schedule, creator, creation time, recipient count, and Push tag match the submitted broadcast in both languages. | F23: Medium | G23: Blocked | H23: Test skipped/blocked. | I23: Automation Bot | J23: 2026-08-11 12:25

Sheet Inbox Broadcast
A1: Inbox Broadcast — Test Cases
A2: Execute each test case in both English and Arabic UI language. Select Status from the dropdown: Pass / Fail / Blocked / Not Executed.
A3: Test Case ID | B3: Test Scenario | C3: Precondition | D3: Test Steps | E3: Expected Result | F3: Priority | G3: Status | H3: Actual Result | I3: Tested By | J3: Date Tested | K3: Remarks
A4: TC-BC-001 | B4: Verify Add Broadcast opens a clean Inbox broadcast creation form. | C4: The user has permission to create Inbox broadcasts. | D4: 1. Log in and open Broadcast > Inbox. 2. Select Add Broadcast. 3. Verify the create page title and all Inbox-specific fields are displayed. 4. Confirm no values from a previously viewed broadcast remain populated. 5. Use Back or Cancel and verify the listing reopens without creating a record. 6. Repeat in the Arabic UI. | E4: Pass | F4: Medium | G4: Pass | H4: Automated check passed. | I4: Automation Bot | J4: 2026-08-31 17:00
A5: TC-BC-002 | B5: Verify From and To date filters return only Inbox broadcasts within inclusive boundaries. | C5: Inbox broadcasts exist before, on, and after known boundary dates. | D5: 1. Open Broadcast > Inbox. 2. Apply a valid From and To range containing known records. 3. Compare each displayed Scheduled Date Time or Created On value with the selected boundaries. 4. Confirm records on both boundary dates are included and out-of-range records are excluded. 5. Test a single-day range and then an invalid range where From is later than To. 6. Clear the filters and repeat in Arabic. | E5: Pass | F5: Medium | G5: Pass | H5: Automated check passed. | I5: Automation Bot | J5: 2026-08-31 17:00
A6: TC-BC-003 | B6: Verify Broadcast Name search returns accurate Inbox matches and handles no-result input. | C6: At least two Inbox broadcasts have distinct known names. | D6: 1. Open Broadcast > Inbox. 2. Enter a complete existing Broadcast Name and submit the search. 3. Search using a unique partial value and different letter casing. 4. Verify every returned row matches the entered value according to the defined search behavior. 5. Search for a nonexistent name, then clear the search. 6. Repeat in Arabic. | E6: Pass | F6: Medium | G6: Pass | H6: Automated check passed. | I6: Automation Bot | J6: 2026-08-31 17:00
A7: TC-BC-004 | B7: Verify Inbox listing columns sort correctly in ascending and descending order. | C7: The Inbox list contains v variety ofaried names, dates, and crea | D7: 1. Open Broadcast > Inbox. 2. Select the Broadcast Name header and record the ascending order; select it again for descending order. 3. Repeat for Scheduled Date Time, Created By, and Created On. 4. Check the first, middle, and last rows after each sort. 5. Confirm blank values, if present, are positioned consistently. 6. Repeat in Arabic. | E7: Pass | F7: Low | G7: Pass | H7: Automated check passed. | I7: Automation Bot | J7: 2026-08-31 17:01
A8: TC-BC-005 | B8: Verify each Inbox row displays the correct channel tag and recipient-count badge. | C8: Use Inbox broadcasts with known recipient counts, including one and multiple recipients. | D8: 1. Open Broadcast > Inbox. 2. Locate the selected broadcasts by name. 3. Confirm each row displays the Inbox tag. 4. Compare the recipient badge with the recipients accepted when the broadcast was created or with the approved source record. 5. Check singular, multiple-recipient, and zero-recipient handling where supported. 6. Repeat in Arabic. | E8: Pass | F8: Medium | G8: Pass | H8: Automated check passed. | I8: Automation Bot | J8: 2026-08-31 17:01
A9: TC-BC-006 | B9: Verify the Inbox row action menu and advanced filters show authorized options and apply correctly. | C9: The list contains Inbox broadcasts in different statuses and the test role's permissions are known. | D9: 1. Open Broadcast > Inbox and open the three-dot menu for a known row. 2. Verify only actions permitted for its status and the logged-in role are shown. 3. Execute each non-destructive option and verify it targets the selected broadcast. 4. Open advanced filters, apply each available criterion individually and in combination. 5. Clear all criteria and confirm the original list returns. 6. Repeat in Arabic. | E9: Pass | F9: Medium | G9: Pass | H9: Automated check passed. | I9: Automation Bot | J9: 2026-08-31 17:01
A10: TC-BC-007 | B10: Verify Regular and Custom modes display the correct Inbox form fields without retaining incompatible values. | C10: The user can create Inbox broadcasts. | D10: 1. Open the Inbox create form. 2. Note the default mode and its visible required fields. 3. Enter distinguishable test values, then switch to the other mode. 4. Verify the field set and required indicators change according to the selected mode. 5. Switch back and check whether values are retained or cleared according to the approved design. 6. Repeat in Arabic. | E10: Pass | F10: Medium | G10: Pass | H10: Automated check passed. | I10: Automation Bot | J10: 2026-08-31 17:01
A11: TC-BC-008 | B11: Verify Broadcast Name is mandatory and accepts only valid Inbox name input. | D11: 1. Open the Inbox create form. 2. Leave Broadcast Name blank, complete other mandatory fields with valid data, and submit. 3. Repeat using spaces only. 4. Enter a valid, unique name containing allowed characters and submit again. 5. If a documented maximum length exists, test values at and above the limit. 6. Repeat in Arabic. | E11: Pass | F11: High | G11: Pass | H11: Automated check passed. | I11: Automation Bot | J11: 2026-08-31 17:01
A12: TC-BC-009 | B12: Verify Department is required and lists only departments available to the logged-in user for Inbox broadcasts. | C12: The test user has access to known departments and is restricted from at least one department if role rules support it. | D12: 1. Open the Inbox create form and expand Department. 2. Compare available values with the user's authorized department list. 3. Leave Department unselected and attempt submission with all other mandatory fields valid. 4. Select an authorized department and continue. 5. Search or scroll for duplicate, inactive, or unauthorized entries. 6. Repeat in Arabic. | E12: Pass | F12: High | G12: Pass | H12: Automated check passed. | I12: Automation Bot | J12: 2026-08-31 17:01
A13: TC-BC-010 | B13: Verify Send Now and Schedule Later modes control Inbox scheduling and date-time validation correctly. | D13: 1. Open the Inbox create form and note the default scheduling mode. 2. Select Send Now and verify no future date-time is required. 3. Select Schedule Later and confirm a date-time picker appears and becomes mandatory. 4. Attempt to select a past time, then select a valid future time in the application's configured time zone. 5. Switch modes and verify hidden schedule values are not submitted unexpectedly. 6. Repeat in Arabic. | E13: Pass | F13: Medium | G13: Pass | H13: Automated check passed. | I13: Automation Bot | J13: 2026-08-31 17:01
A14: TC-BC-011 | B14: Verify Inbox recipient sample files download in Excel and CSV formats with the required template structure. | D14: 1. Open the Inbox create form. 2. Select the Excel sample-file icon and open the downloaded file. 3. Select the CSV icon and open that file. 4. Compare file names, headers, column order, example values, encoding, and mandatory-field guidance with the upload specification. 5. Confirm the templates can be populated and saved without corruption. 6. Repeat from the Arabic UI. | E14: Pass | F14: Medium | G14: Pass | H14: Automated check passed. | I14: Automation Bot | J14: 2026-08-31 17:01
A15: TC-BC-012 | B15: Verify Inbox recipient upload accepts valid Excel/CSV files and rejects unsupported or malformed files. | C15: Prepare valid Excel and CSV files plus files with unsupported extension, missing headers, invalid rows, and excessive size if a limit is documented. | D15: 1. Open the Inbox create form and upload each valid file. 2. Verify the selected file name and accepted recipient count. 3. Replace it with each invalid file and observe validation. 4. Confirm invalid files cannot be submitted and errors identify the reason or row where applicable. 5. Remove the file and verify the control resets. 6. Repeat in Arabic. | E15: Pass | F15: High | G15: Pass | H15: Automated check passed. | I15: Automation Bot | J15: 2026-08-31 17:01
A16: TC-BC-013 | B16: Verify the Inbox recipient Group dropdown loads authorized groups and applies the selected membership accurately. | C16: Known active, inactive, empty, and unauthorized recipient groups exist where supported. | D16: 1. Open the Inbox create form and expand Group. 2. Compare displayed groups with the test user's authorized active groups. 3. Select a known group and compare the shown recipient count with its current valid membership. 4. Change to another group and confirm the count refreshes. 5. Check that inactive, unauthorized, or duplicate groups are absent. 6. Repeat in Arabic. | E16: Pass | F16: Medium | G16: Pass | H16: Automated check passed. | I16: Automation Bot | J16: 2026-08-31 17:01
A17: TC-BC-014 | B17: Verify Manual Entry accepts semicolon-separated valid inbox recipient identifiers and calculates recipients correctly. | C17: Prepare at least three known-valid inbox recipient identifiers, including the exact supported delimiter format. | D17: 1. Open the Inbox create form and choose Manual Entry. 2. Enter one valid value and verify it is recognized. 3. Enter multiple valid values separated by semicolons, with and without a trailing semicolon. 4. Add leading/trailing spaces and a duplicate value to check normalization and duplicate handling. 5. Compare the accepted recipient count with the unique valid entries. 6. Repeat in Arabic. | E17: Pass | F17: High | G17: Pass | H17: Automated check passed. | I17: Automation Bot | J17: 2026-08-31 17:01
A18: TC-BC-015 | B18: Verify exactly one Inbox recipient method is required and conflicting methods cannot be submitted together. | D18: 1. Open the Inbox create form and complete all non-recipient mandatory fields. 2. Submit without File, Group, or Manual Entry. 3. Select File and confirm the other methods are cleared or disabled as designed. 4. Repeat separately with Group and Manual Entry. 5. Attempt to populate two methods by switching controls or using the approved UI test method. 6. Repeat in Arabic. | E18: Pass | F18: High | G18: Pass | H18: Automated check passed. | I18: Automation Bot | J18: 2026-08-31 17:01
A19: TC-BC-016 | B19: Verify User Field lists valid USERFIELDINBOX mappings and applies the selected mapping to Inbox recipients. | C19: At least two active USERFIELDINBOX mappings with known recipient data exist. | D19: 1. Open the Inbox create form and expand User Field. 2. Compare displayed entries with the configured active USERFIELDINBOX mappings. 3. Select each known mapping and verify its label/value is retained. 4. Complete the form with compatible recipient data and submit a test broadcast. 5. Confirm recipient resolution uses the selected field and inactive/duplicate mappings are absent. 6. Repeat in Arabic. | E19: Pass | F19: Medium | G19: Pass | H19: Automated check passed. | I19: Automation Bot | J19: 2026-08-31 17:01
A20: TC-BC-017 | B20: Verify Inbox Expiry Date and Relative Expiry modes display and submit only the applicable expiry controls. | D20: 1. Open the Inbox create form and locate expiry mode. 2. Select Expiry Date and verify an absolute date/time control is shown. 3. Enter a valid value, switch to Relative Expiry, and verify duration controls replace it. 4. Enter a valid relative duration, switch back, and inspect value retention according to design. 5. Submit once in each mode using otherwise valid data. 6. Repeat in Arabic. | E20: Pass | F20: Medium | G20: Pass | H20: Automated check passed. | I20: Automation Bot | J20: 2026-08-31 17:01
A21: TC-BC-018 | B21: Verify absolute Inbox Expiry Date is mandatory, future-dated, and later than the scheduled send time. | D21: 1. Open the Inbox create form and select Expiry Date mode. 2. Complete all other mandatory fields and submit with expiry blank. 3. Enter a past date/time and submit. 4. For Schedule Later, enter an expiry equal to or earlier than the send time. 5. Enter a valid expiry later than the scheduled send and submit. 6. Repeat in Arabic. | E21: Pass | F21: High | G21: Pass | H21: Automated check passed. | I21: Automation Bot | J21: 2026-08-31 17:02
A22: TC-BC-019 | B22: Verify relative Inbox expiry calculates the final expiration time accurately from the actual send time. | C22: Use documented minimum and maximum relative-expiry units. | D22: 1. Open the Inbox create form and select Relative Expiry. 2. Enter a known duration, such as 2 days or the supported equivalent, and schedule a future send. 3. Create the broadcast and record its send and calculated expiry timestamps. 4. Independently calculate send time plus the entered duration and compare. 5. Test minimum, maximum, zero, and above-maximum values. 6. Repeat in Arabic. | E22: Pass | F22: Medium | G22: Pass | H22: Automated check passed. | I22: Automation Bot | J22: 2026-08-31 17:02
A23: TC-BC-020 | B23: Verify Template Name is mandatory and lists only active templates compatible with Inbox and the selected context. | C23: Active, inactive, and channel-incompatible templates exist. | D23: 1. Open the Inbox create form and expand Template Name after selecting required context fields. 2. Compare the list with approved active Inbox templates. 3. Leave it blank and attempt submission. 4. Select a valid template and verify any preview or mapped fields use the correct content. 5. Confirm inactive, unauthorized, or incompatible templates are absent. 6. Repeat in Arabic. | E23: Pass | F23: High | G23: Pass | H23: Automated check passed. | I23: Automation Bot | J23: 2026-08-31 17:02
A24: TC-BC-021 | B24: Verify Schedule creates one valid Inbox broadcast and provides an unambiguous confirmation. | C24: Prepare valid, unique broadcast data and a known recipient set. | D24: 1. Open the Inbox create form and complete every mandatory field with valid data. 2. Review name, department, schedule, recipient source, and template. 3. Select Schedule once and observe button state while processing. 4. Record the success message and any generated reference. 5. Refresh the listing and search for the unique name. 6. Repeat with a second unique case in Arabic. | E24: Blocked | F24: Medium | G24: Blocked | H24: Test skipped/blocked. | I24: Automation Bot | J24: 2026-08-31 17:02
A25: TC-BC-022 | B25: Verify a newly created Inbox broadcast appears in the listing with accurate schedule, creator, recipients, and channel tag. | C25: Create a uniquely named Inbox broadcast with a known future schedule and recipient count. | D25: 1. Return to Broadcast > Inbox after successful creation. 2. Search for the unique Broadcast Name. 3. Compare Scheduled Date Time, Created By, Created On, recipient count, and Inbox tag with the submitted values and logged-in user. 4. Refresh the page and repeat the comparison. 5. Confirm no duplicate row exists. 6. Repeat in Arabic. | E25: Blocked | F25: Medium | G25: Blocked | H25: Test skipped/blocked. | I25: Automation Bot | J25: 2026-08-31 17:02

Sheet MessageTemplate
A1: Dictionaries — Test Cases
A2: Execute each test case in both English and Arabic UI language. Select Status from the dropdown: Pass / Fail / Blocked / Not Executed.
A3: Test Case ID | B3: Test Scenario | C3: Precondition | D3: Test Steps | E3: Expected Result | F3: Priority | G3: Status | H3: Actual Result | I3: Tested By | J3: Date Tested | K3: Remarks
A4: TC-DIC-001 | B4: Verify Add opens a clean Message Template creation form. | C4: The user has permission to manage message templates. | D4: 1. Open Dictionaries > MessageTemplate. 2. Select Add. 3. Verify Template Name, Department, Channel, Template Type, and English/Arabic content controls are displayed. 4. Confirm required indicators and default selections are correct. 5. Cancel or go back and verify no template is created. 6. Repeat in Arabic. | E4: Pass | F4: Pass | G4: Automated check passed. | H4: Automated check passed. | I4: Automation Bot | J4: 2026-08-28 21:15
A5: TC-DIC-002 | B5: Verify the Channel filter returns only SMS, Email, Push, or Inbox templates as selected. | C5: At least one template exists for every supported channel. | D5: 1. Open MessageTemplate. 2. Select SMS and verify each row's channel/type badge. 3. Repeat for Email, Push, and Inbox. 4. Combine a channel selection with a Template Name search if supported. 5. Clear the filter and verify all authorized channels return. 6. Repeat in Arabic. | E5: Pass | F5: Pass | G5: Automated check passed. | H5: Automated check passed. | I5: Automation Bot | J5: 2026-08-28 21:15
A6: TC-DIC-003 | B6: Verify Template Name search returns accurate matches and handles no-result input. | C6: Templates with distinct known names exist. | D6: 1. Open MessageTemplate. 2. Search using a complete existing name. 3. Search using a unique partial value and different letter casing. 4. Verify every result matches the supported search rule. 5. Search for a nonexistent name, then clear the search. 6. Repeat in Arabic. | E6: Pass | F6: Pass | G6: Automated check passed. | H6: Automated check passed. | I6: Automation Bot | J6: 2026-08-28 21:15
A7: TC-DIC-004 | B7: Verify Message Template columns sort correctly in ascending and descending order. | C7: The list contains varied template names, types, users, and dates. | D7: 1. Sort Template Name ascending and descending. 2. Repeat for Template Type, Created By, Created Date, Modified By, and Modified Date. 3. Check the first, middle, and last rows after each sort. 4. Confirm dates use chronological order and blank modified values are positioned consistently. 5. Verify no rows are lost or duplicated. 6. Repeat in Arabic. | E7: Pass | F7: Pass | G7: Automated check passed. | H7: Automated check passed. | I7: Automation Bot | J7: 2026-08-28 21:16
A8: TC-DIC-005 | B8: Verify Template Name is mandatory and accepts only valid unique input. | D8: 1. Open Add Message Template. 2. Complete other mandatory fields and submit with Template Name blank, then spaces only. 3. Enter a valid unique name and submit. 4. Test documented maximum length and disallowed characters. 5. Attempt the name of an existing template, including case and whitespace variations. 6. Repeat in Arabic. | E8: Blank, invalid, overlength, or duplicate names are rejected beside the field; a valid unique name is accepted and stored exactly according to normalization rules. | F8: Pass | G8: Automated check passed. | H8: Automation Bot | I8: 2026-08-28 20:53 | J8: 2026-08-19 17:28
A9: TC-DIC-006 | B9: Verify Department selection is mandatory, supports the configured selection mode, and removable selections work. | C9: Multiple authorized departments exist. | D9: 1. Open Add Message Template and expand Department. 2. Verify only active authorized departments are listed once. 3. Submit with no selection. 4. Select one department and, if multi-select is supported, select additional departments. 5. Remove a selected item using its x control and verify the saved selection set. 6. Repeat in Arabic. | E9: No-selection submission is blocked; single/multiple selection follows configuration, x removes only the chosen item, and only authorized active departments can be saved. | F9: Pass | G9: Automated check passed. | H9: Automation Bot | I9: 2026-08-28 20:53 | J9: 2026-08-19 17:28
